---
title: "知らないとハマる Next.js のエラーハンドリング"
emoji: "⚠"
type: "tech" # tech: 技術記事 / idea: アイデア
topics: ["nextjs", "react"]
published: false
---

Next.js アプリケーションを作っていてエラーハンドリングでハマったので、どういうハマり方をして最終的にどうなったかという話を時系列順で書いていきます。

## 環境

- Next.js v15.0.3
- App Router 使用

## その1: Server Component で throw したカスタムエラーを Client Component の Error Boundary では受け取れない

### 間違いパターン

ありそうな実装パターンを書きます。

```typescript
const HogeContainer = async () => {
  const users = await getUsers()
  return <HogePresentation users={users} />
}
```

Server Component で非同期関数である getUsers を実行して users を Client Component である HogePresentation に渡しています。
getUsers 関数は、中でどこぞの API を叩いて users を取得します。叩いた API がエラーを返した場合、HttpError というカスタムエラーを throw します。

```typescript
class HttpError extends Error {
  constructor(message: string, status: number) {
    super(message)
    this.status = status
  }
}

const getUsers = async () => {
  const res = await fetch('/users')

  if (!res.ok) {
    throw new HttpError('なんかエラー', res.status)
  }
  
  const json = await res.json()

  return json
}
```

HogeContainer の中でエラーが throw された場合、それを app ディレクトリ直下の [error.tsx](https://nextjs.org/docs/app/building-your-application/routing/error-handling) で受けることにします。

```typescript
'use client'

type Props = {
  error: Error & { digest?: string }
  reset: () => void
}

export default function Error({ error, reset }: Props) {
  useEffect(() => {
    // Log the error to an error reporting service
    console.error(error)
  }, [error])

  if (error instanceof HttpError) {
    switch (error.status) {
      case 400:
        return 'Bad Request'
      
      case 401:
        return 'Unauthorized'
      
      default:
        return 'Unexpected'
    }
  }
  
  return 'Unexpected'
}
```

これで、getUsers が throw した HttpError の status に応じてページにエラーメッセージを表示することができます。

### 何がだめか

実際にこの処理を動かしてみると、getUsers がどんなステータスでエラーを投げたとしても、画面には「Unexpected」が表示されます。

なぜかというと、Server Component でカスタムエラーを throw して error.tsx にフォールバックさせる場合、error.tsx に渡される error props は標準の Error Class に変換されます。Server と Client の境界をまたぐので当然ですね。
error.tsx を Server Component にすれば良いのでは？となりそうですが、error.tsx は Client Component を強制されます。

そのため、error.tsx で受け取る error は `error instanceof HttpError` で false になるし、status というプロパティを持っていません。

## その2: production mode では Server Comopnent で throw したエラーの内容は Client Comopnent からはわからない

### 間違いパターン

ということで、カスタムエラーを投げても意味がないので、標準の Error で message を工夫したくなります。

```typescript
const HogeContainer = async () => {
  try {
    const users = await getUsers()
    return <HogePresentation users={users} />
  } catch (e) {
    if (error instanceof HttpError) {
      throw new Error(`${error.status}/${error.message}`)
    }
    
    throw new Error(error.message)
  }
}
```

```typescript
export default function Error({ error, reset }: Props) {
  const [status, message] = error.message.split('/')

  if (status) {
    switch (error.status) {
      case '400':
        return 'Bad Request'
      
      case '401':
        return 'Unauthorized'
      
      default:
        return 'Unexpected'
    }
  }
  
  return 'Unexpected'
}
```

HttpError の status を標準の Error の message に文字列として埋め込んで直しています。
こうすると、想定通り getUsers から投げられた HttpError の status にあわせたエラーメッセージが表示されるようになります。

### 何がだめか

しかし実はこの書き方で動くのは dev mode のみで、 `next build && next start` で production mode で動かした場合は想定通りの挙動をしません。

production mode で動かしてエラーを発生させた際に error.tsx に props として渡される error の中身を見ると以下のようになっています。

```
Error: An error occurred in the Server Components render. The specific message is omitted in production builds to avoid leaking sensitive details. A digest property is included on this error instance which may provide additional details about the nature of the error.
```

(Server Component のレンダリング中になんかしらのエラーが起きたよって言ってる)

これは production mode の場合、サーバー側で発生したエラーの内容をクライアントにそのまま渡してしまうとユーザーに生のエラーが見えてしまうため、Next.js 側でエラーの中身を変換してくれるゆえにこうなります。

## 解決策

ということでここからはいろいろな解決方法がありますが、これまでのコードから挙動を変えずに動くようにするにはどうするかという視点での解決策を書きます。
(そもそも error.tsx で画面全体をエラーにするのではなくページ側で局所的に対応した方が良いとかはある)

まず HttpError に serialize, deserialize メソッドを用意します。

```typescript
class HttpError extends Error {
  constructor(message: string, status: number) {
    super(message)
    this.status = status
  }
  
  serialize() {
    return {
      message: this.message,
      status: this.status,
    }
  }
  
  public deserialize(data: any) {
    return new HttpError(data.message, data.status)
  }
}
```

そして HogeContainer 内でこのエラーを Client Component に渡します。

```typescript
const HogeContainer = async () => {
  try {
    const users = await getUsers()
    return <HogePresentation users={users} />
  } catch (e) {
    if (error instanceof HttpError) {
      return <ThrowHttpError serializedError={e.serialize()} />
    }
    
    throw new Error(error.message)
  }
}
```

ThrowHttpError は Client Component になっていて、受け取ったエラーをそのまま throw するだけのコンポーネントです。

```typescript
type Props = {
  serializedError: any
}

const ThrowHttpError = ({ serializedError }: Props) => {
  throw HttpError.deserialize(serializedError)
  return null
}
```

Client Component からエラーを投げ直しているので、error.tsx はそのエラーをそのまま受け取ることができます。

```typescript
export default function Error({ error, reset }: Props) {
  if (error instanceof HttpError) {
    switch (error.status) {
      case 400:
        return 'Bad Request'
      
      case 401:
        return 'Unauthorized'
      
      default:
        return 'Unexpected'
    }
  }
  
  return 'Unexpected'
}
```
